Workbook

Sheet README
A1: THE UNLOX ACADEMY - DA/DS TRACK
A2: Excel Minor Project - Sales Operations Analytics
A3: Interview-Grade Data Analytics Assessment · 100 Marks
A5: THE SCENARIO
A6: You have just joined the analytics team at a fast-growing multi-category retailer operating across 6 Indian cities.
A7: The head of sales has handed you 5 raw data files - Orders, Customers, Products, Sales Reps, and Targets - and asked
A8: you to answer a set of business questions before the leadership review tomorrow morning.
A10: The data is REAL-WORLD messy: duplicates, missing references, inconsistent case, invalid records, discontinued SKUs.
A11: Part of the assessment is spotting and handling these issues correctly. A wrong-looking answer isn't always wrong -
A12: sometimes the data itself is telling a story.
A14: RULES OF THE ASSESSMENT
A15: 1. Write your answer in the YELLOW cells on each question sheet. Empty answer cell = 0 marks.
... A22: MARKS DISTRIBUTION
A23: Section | B23: Topic | C23: Questions | D23: Marks
A24: Q1 | B24: Lookup Functions (VLOOKUP, INDEX-MATCH, chained lookups) | C24: 8 | D24: 25
A25: Q2 | B25: Data Cleaning & Quality Diagnostics | C25: 6 | D25: 20
A26: Q3 | B26: Conditional Aggregation (SUMIFS, COUNTIFS, IF logic) | C26: 6 | D26: 25
A27: Q4 | B27: Pivot Tables (2D pivots, % of total, calculated fields) | C27: 5 | D27: 20
A28: Q5 | B28: Advanced (Ranking, Running Totals, Multi-condition) | C28: 5 | D28: 10
B29: TOTAL | C29: 30 | D29: 100
A32: PERFORMANCE TIERS
A33: Marks | B33: Tier | C33: Interview Verdict
A34: 85 - 100 | B34: Excellent | C34: Round 1 clear - Excel not a concern
A35: 70 - 84 | B35: Good | C35: Round 1 clear with minor gaps
A36: 55 - 69 | B36: Borderline | C36: Round 1 uncertain - needs revision
A37: 40 - 54 | B37: Weak | C37: Round 1 likely reject - 2 weeks of practice needed
A38: < 40 | B38: Insufficient | C38: Round 1 reject - foundational gaps
A41: DATA SHEETS OVERVIEW
A42: Sheet | B42: Rows | C42: Key Columns | D42: Joins to
A43: Orders | B43: ~2000 | C43: order_id, order_date, customer_id, product_id, sales_rep_id, quantity, unit_price, discount_pct, final_amount, payment_status, ship_city | D43: All others
A44: Customers | B44: 300 | C44: customer_id (PK), customer_name, age, city, segment, signup_date | D44: Orders via customer_id
A45: Products | B45: 60 | C45: product_id (PK), product_name, category, unit_cost, unit_price, is_active | D45: Orders via product_id
A46: Sales_Reps | B46: 30 | C46: rep_id (PK), rep_name, region, hire_date, team_lead_id | D46: Orders via sales_rep_id, self-join via team_lead_id
A47: Targets | B47: 30 × 12 | C47: rep_id (PK), Jan-24 through Dec-24 monthly target values | D47: Sales_Reps via rep_id

Sheet Detail1
A1: Details for Sum of final_amount - Quarters (order_date): Qtr4
A3: order_id | B3: order_date | C3: customer_id | D3: product_id | E3: sales_rep_id | F3: quantity | G3: unit_price | H3: discount_pct | I3: final_amount | J3: payment_status | K3: ship_city | L3: dup_flag | M3: is_active | N3: category | O3: segment | P3: age | Q3: region | R3: unit_cost
A4: ORD-01998 | B4: 45592 | C4: CUST-0030 | D4: PROD-029 | E4: R011 | F4: 4 | G4: 2210 | H4: 18.2 | I4: 7231.12 | J4: Pending | K4: Bengaluru | L4: 0 | M4: TRUE | N4: Grocery | O4: Corporate | P4: 43 | Q4: South | R4: 1010
A5: ORD-01997 | B5: 45585 | C5: CUST-0135 | D5: PROD-006 | E5: R017 | F5: 6 | G5: 3970 | H5: 5.8 | I5: 22438.44 | J5: Pending | K5: Pune | L5: 0 | M5: TRUE | N5: Electronics | O5: SMB | P5: 24 | Q5: East | R5: 2865
A6: ORD-01991 | B6: 45616 | C6: CUST-0083 | D6: PROD-048 | E6: R013 | F6: 5 | G6: 5100 | H6: 28.4 | I6: 18258 | J6: Completed | K6: Bengaluru | L6: 0 | M6: TRUE | N6: Beauty | O6: Corporate | P6: 31 | Q6: South | R6: 2237
A7: ORD-01990 | B7: 45645 | C7: CUST-0159 | D7: PROD-035 | E7: R006 | F7: 10 | G7: 1090 | H7: 29.2 | I7: 7717.2 | J7: Cancelled | K7: Hyderabad | L7: 0 | M7: TRUE | N7: Home | O7: Retail | P7: 32 | Q7: North | R7: 464
A8: ORD-00005 | B8: 45611 | C8: CUST-0180 | D8: PROD-012 | E8: R008 | F8: 1 | G8: 3160 | H8: 26 | I8: 2338.4 | J8: Completed | K8: Chennai | L8: 0 | M8: TRUE | N8: Apparel | O8: Retail | P8: 36 | Q8: North | R8: 1886
A9: ORD-01980 | B9: 45635 | C9: CUST-0227 | D9: PROD-033 | E9: R006 | F9: 10 | G9: 2030 | H9: 29.2 | I9: 14372.4 | J9: Completed | K9: Bengaluru | L9: 0 | M9: TRUE | N9: Home | O9: SMB | P9: 44 | Q9: North | R9: 1143
A10: ORD-01977 | B10: 45589 | C10: CUST-0174 | D10: PROD-053 | E10: R028 | F10: 3 | G10: 470 | H10: 14.2 | I10: 1209.78 | J10: Completed | K10: Pune | L10: 0 | M10: FALSE | N10: Sports | O10: Retail | P10: 54 | Q10: West | R10: 302
A11: ORD-00008 | B11: 45617 | C11: CUST-0281 | D11: PROD-007 | E11: R019 | F11: 8 | G11: 1430 | H11: 2.4 | I11: 11165.44 | J11: Completed | K11: Bengaluru | L11: 0 | M11: TRUE | N11: Electronics | O11: Corporate | P11: 57 | Q11: East | R11: 861
A12: ORD-01967 | B12: 45586 | C12: CUST-0139 | D12: PROD-018 | E12: R030 | F12: 3 | G12: 3560 | H12: 23.6 | I12: 8159.52 | J12: Completed | K12: Hyderabad | L12: 0 | M12: TRUE | N12: Apparel | O12: SMB | P12: 65 | Q12: West | R12: 2629
A13: ORD-01959 | B13: 45598 | C13: CUST-0138 | D13: PROD-026 | E13: R020 | F13: 10 | G13: 4070 | H13: 11.6 | I13: 35978.8 | J13: Completed | K13: Chennai | L13: 0 | M13: TRUE | N13: Grocery | O13: Retail | P13: 24 | Q13: East | R13: 2027
A14: ORD-01958 | B14: 45633 | C14: CUST-0249 | D14: PROD-009 | E14: R028 | F14: 4 | G14: 1220 | H14: 2.7 | I14: 4748.24 | J14: Completed | K14: Mumbai | L14: 0 | M14: TRUE | N14: Electronics | O14: Retail | P14: 44 | Q14: West | R14: 517
A15: ORD-01952 | B15: 45618 | C15: CUST-0080 | D15: PROD-003 | E15: R020 | F15: 6 | G15: 3570 | H15: 28.5 | I15: 15315.3 | J15: Cancelled | K15: Pune | L15: 0 | M15: TRUE | N15: Electronics | O15: SMB | P15: 30 | Q15: East | R15: 1665
... A32: ORD-01890 | B32: 45621 | C32: CUST-0022 | D32: PROD-058 | E32: R013 | F32: 4 | G32: 2400 | H32: 16.6 | I32: 8006.4 | J32: Pending | K32: Bengaluru | L32: 0 | M32: TRUE | N32: Sports | O32: Corporate | P32: 55 | Q32: South | R32: 974
A33: ORD-01884 | B33: 45622 | C33: CUST-9967 | D33: PROD-029 | E33: R029 | F33: 3 | G33: 2210 | H33: 8.5 | I33: 6066.45 | J33: Completed | K33: Delhi | L33: 0 | M33: TRUE | N33: Grocery | O33: #N/A | P33: #N/A | Q33: West | R33: 1010
A34: ORD-00031 | B34: 45569 | C34: CUST-0241 | D34: PROD-030 | E34: R006 | F34: 7 | G34: 970 | H34: 29.8 | I34: 4766.58 | J34: Completed | K34: Pune | L34: 0 | M34: TRUE | N34: Grocery | O34: Corporate | P34: 47 | Q34: North | R34: 434
A35: ORD-00032 | B35: 45641 | C35: CUST-0035 | D35: PROD-021 | E35: R026 | F35: 4 | G35: 2760 | H35: 5.9 | I35: 10388.64 | J35: Completed | K35: Hyderabad | L35: 0 | M35: TRUE | N35: Grocery | O35: Retail | P35: 53 | Q35: West | R35: 1435
A36: ORD-01880 | B36: 45588 | C36: CUST-0251 | D36: PROD-032 | E36: R002 | F36: 1 | G36: 370 | H36: 27 | I36: 270.1 | J36: Pending | K36: Mumbai | L36: 0 | M36: TRUE | N36: Home | O36: Retail | P36: 44 | Q36: North | R36: 288
A37: ORD-00034 | B37: 45576 | C37: CUST-0064 | D37: PROD-036 | E37: R019 | F37: 1 | G37: 3250 | H37: 10.7 | I37: 2902.25 | J37: Completed | K37: Hyderabad | L37: 0 | M37: TRUE | N37: Home | O37: SMB | P37: 40 | Q37: East | R37: 1556
A38: ORD-01879 | B38: 45629 | C38: CUST-0222 | D38: PROD-022 | E38: R002 | F38: 4 | G38: 2270 | H38: 15.8 | I38: 7645.36 | J38: Completed | K38: Chennai | L38: 0 | M38: TRUE | N38: Grocery | O38: Retail | P38: 37 | Q38: North | R38: 1412
A39: ORD-01876 | B39: 45645 | C39: CUST-0028 | D39: PROD-018 | E39: R024 | F39: 5 | G39: 3560 | H39: 24 | I39: 13528 | J39: Completed | K39: Bengaluru | L39: 0 | M39: TRUE | N39: Apparel | O39: Retail | P39: 59 | Q39: West | R39: 2629
A40: ORD-00037 | B40: 45646 | C40: CUST-0177 | D40: PROD-038 | E40: R009 | F40: 2 | G40: 5490 | H40: 21.1 | I40: 8663.22 | J40: Cancelled | K40: Mumbai | L40: 0 | M40: TRUE | N40: Home | O40: SMB | P40: 36 | Q40: South | R40: 2549
A41: ORD-01871 | B41: 45644 | C41: CUST-0286 | D41: PROD-023 | E41: R015 | F41: 9 | G41: 2380 | H41: 8.1 | I41: 19684.98 | J41: Cancelled | K41: Delhi | L41: 0 | M41: TRUE | N41: Grocery | O41: Retail | P41: 62 | Q41: South | R41: 1182
A42: ORD-01869 | B42: 45623 | C42: CUST-0239 | D42: PROD-031 | E42: R009 | F42: 3 | G42: 3730 | H42: 18.1 | I42: 9164.61 | J42: Completed | K42: Mumbai | L42: 0 | M42: TRUE | N42: Home | O42: Retail | P42: 61 | Q42: South | R42: 2135
A43: ORD-00040 | B43: 45599 | C43: CUST-0283 | D43: PROD-044 | E43: R023 | F43: 9 | G43: 1650 | H43: 11.6 | I43: 13127.4 | J43: Completed | K43: Delhi | L43: 0 | M43: TRUE | N43: Beauty | O43: SMB | P43: 50 | Q43: East | R43: 1222
A44: ORD-00041 | B44: 45606 | C44: CUST-9507 | D44: PROD-038 | E44: R006 | F44: 4 | G44: 5490 | H44: 12.8 | I44: 19149.12 | J44: Cancelled | K44: Chennai | L44: 0 | M44: TRUE | N44: Home | O44: #N/A | P44: #N/A | Q44: North | R44: 2549
A45: ORD-01866 | B45: 45648 | C45: CUST-0076 | D45: PROD-025 | E45: R002 | F45: 2 | G45: 4060 | H45: 11.3 | I45: 7202.44 | J45: Completed | K45: Mumbai | L45: 0 | M45: TRUE | N45: Grocery | O45: Retail | P45: 38 | Q45: North | R45: 2911
A46: ORD-01864 | B46: 45627 | C46: CUST-0251 | D46: PROD-015 | E46: R001 | F46: 6 | G46: 2720 | H46: 25.1 | I46: 12223.68 | J46: Cancelled | K46: Mumbai | L46: 0 | M46: TRUE | N46: Apparel | O46: Retail | P46: 44 | Q46: North | R46: 1962
A47: ORD-01863 | B47: 45634 | C47: CUST-0153 | D47: PROD-055 | E47: R014 | F47: 4 | G47: 2860 | H47: 14.3 | I47: 9804.08 | J47: Completed | K47: Mumbai | L47: 0 | M47: TRUE | N47: Sports | O47: Retail | P47: 35 | Q47: South | R47: 2028
A48: ORD-01858 | B48: 45652 | C48: CUST-0044 | D48: PROD-058 | E48: R027 | F48: 3 | G48: 2400 | H48: 20.7 | I48: 5709.6 | J48: Completed | K48: Hyderabad | L48: 0 | M48: TRUE | N48: Sports | O48: SMB | P48: 29 | Q48: West | R48: 974
A49: ORD-01853 | B49: 45650 | C49: CUST-0277 | D49: PROD-009 | E49: R017 | F49: 5 | G49: 1220 | H49: 18.7 | I49: 4959.3 | J49: Completed | K49: Chennai | L49: 0 | M49: TRUE | N49: Electronics | O49: Corporate | P49: 34 | Q49: East | R49: 517
A50: ORD-01852 | B50: 45605 | C50: CUST-0008 | D50: PROD-026 | E50: R010 | F50: 6 | G50: 4070 | H50: 28.9 | I50: 17362.62 | J50: Completed | K50: Pune | L50: 0 | M50: TRUE | N50: Grocery | O50: SMB | P50: 39 | Q50: South | R50: 2027
A51: ORD-01849 | B51: 45569 | C51: CUST-0217 | D51: PROD-039 | E51: R017 | F51: 7 | G51: 4610 | H51: 0.9 | I51: 31979.57 | J51: Completed | K51: Pune | L51: 0 | M51: TRUE | N51: Home | O51: SMB | P51: 59 | Q51: East | R51: 1850
A52: ORD-01841 | B52: 45605 | C52: CUST-0286 | D52: PROD-036 | E52: R025 | F52: 3 | G52: 3250 | H52: 19.6 | I52: 7839 | J52: Pending | K52: Delhi | L52: 0 | M52: TRUE | N52: Home | O52: Retail | P52: 62 | Q52: West | R52: 1556
A53: ORD-01837 | B53: 45647 | C53: CUST-0174 | D53: PROD-017 | E53: R006 | F53: 2 | G53: 2510 | H53: 28.2 | I53: 3604.36 | J53: Completed | K53: Pune | L53: 0 | M53: FALSE | N53: Apparel | O53: Retail | P53: 54 | Q53: North | R53: 1075
A54: ORD-01834 | B54: 45593 | C54: CUST-0242 | D54: PROD-017 | E54: R020 | F54: 4 | G54: 2510 | H54: 23.2 | I54: 7710.72 | J54: Completed | K54: Chennai | L54: 0 | M54: FALSE | N54: Apparel | O54: SMB | P54: 59 | Q54: East | R54: 1075
A55: ORD-01832 | B55: 45633 | C55: CUST-0223 | D55: PROD-055 | E55: R004 | F55: 6 | G55: 2860 | H55: 10.5 | I55: 15358.2 | J55: Cancelled | K55: Bengaluru | L55: 0 | M55: TRUE | N55: Sports | O55: Retail | P55: 46 | Q55: North | R55: 2028
A56: ORD-00053 | B56: 45616 | C56: CUST-0180 | D56: PROD-027 | E56: R013 | F56: 5 | G56: 3780 | H56: 18.5 | I56: 15403.5 | J56: Completed | K56: Chennai | L56: 0 | M56: TRUE | N56: Grocery | O56: Retail | P56: 36 | Q56: South | R56: 2436
... A184: ORD-01435 | B184: 45598 | C184: CUST-0130 | D184: PROD-018 | E184: R002 | F184: 5 | G184: 3560 | H184: 19.4 | I184: 14346.8 | J184: Pending | K184: Bengaluru | L184: 0 | M184: TRUE | N184: Apparel | O184: Corporate | P184: 41 | Q184: North | R184: 2629
...

Sheet Detail2
A1: Details for Sum of final_amount - Quarters (order_date): Qtr4
A3: order_id | B3: order_date | C3: customer_id | D3: product_id | E3: sales_rep_id | F3: quantity | G3: unit_price | H3: discount_pct | I3: final_amount | J3: payment_status | K3: ship_city | L3: dup_flag | M3: is_active | N3: category | O3: segment | P3: age | Q3: region | R3: unit_cost
A4: ORD-01998 | B4: 45592 | C4: CUST-0030 | D4: PROD-029 | E4: R011 | F4: 4 | G4: 2210 | H4: 18.2 | I4: 7231.12 | J4: Pending | K4: Bengaluru | L4: 0 | M4: TRUE | N4: Grocery | O4: Corporate | P4: 43 | Q4: South | R4: 1010
A5: ORD-01997 | B5: 45585 | C5: CUST-0135 | D5: PROD-006 | E5: R017 | F5: 6 | G5: 3970 | H5: 5.8 | I5: 22438.44 | J5: Pending | K5: Pune | L5: 0 | M5: TRUE | N5: Electronics | O5: SMB | P5: 24 | Q5: East | R5: 2865
A6: ORD-01991 | B6: 45616 | C6: CUST-0083 | D6: PROD-048 | E6: R013 | F6: 5 | G6: 5100 | H6: 28.4 | I6: 18258 | J6: Completed | K6: Bengaluru | L6: 0 | M6: TRUE | N6: Beauty | O6: Corporate | P6: 31 | Q6: South | R6: 2237
A7: ORD-01990 | B7: 45645 | C7: CUST-0159 | D7: PROD-035 | E7: R006 | F7: 10 | G7: 1090 | H7: 29.2 | I7: 7717.2 | J7: Cancelled | K7: Hyderabad | L7: 0 | M7: TRUE | N7: Home | O7: Retail | P7: 32 | Q7: North | R7: 464
A8: ORD-00005 | B8: 45611 | C8: CUST-0180 | D8: PROD-012 | E8: R008 | F8: 1 | G8: 3160 | H8: 26 | I8: 2338.4 | J8: Completed | K8: Chennai | L8: 0 | M8: TRUE | N8: Apparel | O8: Retail | P8: 36 | Q8: North | R8: 1886
A9: ORD-01980 | B9: 45635 | C9: CUST-0227 | D9: PROD-033 | E9: R006 | F9: 10 | G9: 2030 | H9: 29.2 | I9: 14372.4 | J9: Completed | K9: Bengaluru | L9: 0 | M9: TRUE | N9: Home | O9: SMB | P9: 44 | Q9: North | R9: 1143
A10: ORD-01977 | B10: 45589 | C10: CUST-0174 | D10: PROD-053 | E10: R028 | F10: 3 | G10: 470 | H10: 14.2 | I10: 1209.78 | J10: Completed | K10: Pune | L10: 0 | M10: FALSE | N10: Sports | O10: Retail | P10: 54 | Q10: West | R10: 302
A11: ORD-00008 | B11: 45617 | C11: CUST-0281 | D11: PROD-007 | E11: R019 | F11: 8 | G11: 1430 | H11: 2.4 | I11: 11165.44 | J11: Completed | K11: Bengaluru | L11: 0 | M11: TRUE | N11: Electronics | O11: Corporate | P11: 57 | Q11: East | R11: 861
A12: ORD-01967 | B12: 45586 | C12: CUST-0139 | D12: PROD-018 | E12: R030 | F12: 3 | G12: 3560 | H12: 23.6 | I12: 8159.52 | J12: Completed | K12: Hyderabad | L12: 0 | M12: TRUE | N12: Apparel | O12: SMB | P12: 65 | Q12: West | R12: 2629
A13: ORD-01959 | B13: 45598 | C13: CUST-0138 | D13: PROD-026 | E13: R020 | F13: 10 | G13: 4070 | H13: 11.6 | I13: 35978.8 | J13: Completed | K13: Chennai | L13: 0 | M13: TRUE | N13: Grocery | O13: Retail | P13: 24 | Q13: East | R13: 2027
A14: ORD-01958 | B14: 45633 | C14: CUST-0249 | D14: PROD-009 | E14: R028 | F14: 4 | G14: 1220 | H14: 2.7 | I14: 4748.24 | J14: Completed | K14: Mumbai | L14: 0 | M14: TRUE | N14: Electronics | O14: Retail | P14: 44 | Q14: West | R14: 517
A15: ORD-01952 | B15: 45618 | C15: CUST-0080 | D15: PROD-003 | E15: R020 | F15: 6 | G15: 3570 | H15: 28.5 | I15: 15315.3 | J15: Cancelled | K15: Pune | L15: 0 | M15: TRUE | N15: Electronics | O15: SMB | P15: 30 | Q15: East | R15: 1665
... A32: ORD-01890 | B32: 45621 | C32: CUST-0022 | D32: PROD-058 | E32: R013 | F32: 4 | G32: 2400 | H32: 16.6 | I32: 8006.4 | J32: Pending | K32: Bengaluru | L32: 0 | M32: TRUE | N32: Sports | O32: Corporate | P32: 55 | Q32: South | R32: 974
A33: ORD-01884 | B33: 45622 | C33: CUST-9967 | D33: PROD-029 | E33: R029 | F33: 3 | G33: 2210 | H33: 8.5 | I33: 6066.45 | J33: Completed | K33: Delhi | L33: 0 | M33: TRUE | N33: Grocery | O33: #N/A | P33: #N/A | Q33: West | R33: 1010
A34: ORD-00031 | B34: 45569 | C34: CUST-0241 | D34: PROD-030 | E34: R006 | F34: 7 | G34: 970 | H34: 29.8 | I34: 4766.58 | J34: Completed | K34: Pune | L34: 0 | M34: TRUE | N34: Grocery | O34: Corporate | P34: 47 | Q34: North | R34: 434
A35: ORD-00032 | B35: 45641 | C35: CUST-0035 | D35: PROD-021 | E35: R026 | F35: 4 | G35: 2760 | H35: 5.9 | I35: 10388.64 | J35: Completed | K35: Hyderabad | L35: 0 | M35: TRUE | N35: Grocery | O35: Retail | P35: 53 | Q35: West | R35: 1435
A36: ORD-01880 | B36: 45588 | C36: CUST-0251 | D36: PROD-032 | E36: R002 | F36: 1 | G36: 370 | H36: 27 | I36: 270.1 | J36: Pending | K36: Mumbai | L36: 0 | M36: TRUE | N36: Home | O36: Retail | P36: 44 | Q36: North | R36: 288
A37: ORD-00034 | B37: 45576 | C37: CUST-0064 | D37: PROD-036 | E37: R019 | F37: 1 | G37: 3250 | H37: 10.7 | I37: 2902.25 | J37: Completed | K37: Hyderabad | L37: 0 | M37: TRUE | N37: Home | O37: SMB | P37: 40 | Q37: East | R37: 1556
A38: ORD-01879 | B38: 45629 | C38: CUST-0222 | D38: PROD-022 | E38: R002 | F38: 4 | G38: 2270 | H38: 15.8 | I38: 7645.36 | J38: Completed | K38: Chennai | L38: 0 | M38: TRUE | N38: Grocery | O38: Retail | P38: 37 | Q38: North | R38: 1412
A39: ORD-01876 | B39: 45645 | C39: CUST-0028 | D39: PROD-018 | E39: R024 | F39: 5 | G39: 3560 | H39: 24 | I39: 13528 | J39: Completed | K39: Bengaluru | L39: 0 | M39: TRUE | N39: Apparel | O39: Retail | P39: 59 | Q39: West | R39: 2629
A40: ORD-00037 | B40: 45646 | C40: CUST-0177 | D40: PROD-038 | E40: R009 | F40: 2 | G40: 5490 | H40: 21.1 | I40: 8663.22 | J40: Cancelled | K40: Mumbai | L40: 0 | M40: TRUE | N40: Home | O40: SMB | P40: 36 | Q40: South | R40: 2549
A41: ORD-01871 | B41: 45644 | C41: CUST-0286 | D41: PROD-023 | E41: R015 | F41: 9 | G41: 2380 | H41: 8.1 | I41: 19684.98 | J41: Cancelled | K41: Delhi | L41: 0 | M41: TRUE | N41: Grocery | O41: Retail | P41: 62 | Q41: South | R41: 1182
A42: ORD-01869 | B42: 45623 | C42: CUST-0239 | D42: PROD-031 | E42: R009 | F42: 3 | G42: 3730 | H42: 18.1 | I42: 9164.61 | J42: Completed | K42: Mumbai | L42: 0 | M42: TRUE | N42: Home | O42: Retail | P42: 61 | Q42: South | R42: 2135
A43: ORD-00040 | B43: 45599 | C43: CUST-0283 | D43: PROD-044 | E43: R023 | F43: 9 | G43: 1650 | H43: 11.6 | I43: 13127.4 | J43: Completed | K43: Delhi | L43: 0 | M43: TRUE | N43: Beauty | O43: SMB | P43: 50 | Q43: East | R43: 1222
A44: ORD-00041 | B44: 45606 | C44: CUST-9507 | D44: PROD-038 | E44: R006 | F44: 4 | G44: 5490 | H44: 12.8 | I44: 19149.12 | J44: Cancelled | K44: Chennai | L44: 0 | M44: TRUE | N44: Home | O44: #N/A | P44: #N/A | Q44: North | R44: 2549
A45: ORD-01866 | B45: 45648 | C45: CUST-0076 | D45: PROD-025 | E45: R002 | F45: 2 | G45: 4060 | H45: 11.3 | I45: 7202.44 | J45: Completed | K45: Mumbai | L45: 0 | M45: TRUE | N45: Grocery | O45: Retail | P45: 38 | Q45: North | R45: 2911
A46: ORD-01864 | B46: 45627 | C46: CUST-0251 | D46: PROD-015 | E46: R001 | F46: 6 | G46: 2720 | H46: 25.1 | I46: 12223.68 | J46: Cancelled | K46: Mumbai | L46: 0 | M46: TRUE | N46: Apparel | O46: Retail | P46: 44 | Q46: North | R46: 1962
A47: ORD-01863 | B47: 45634 | C47: CUST-0153 | D47: PROD-055 | E47: R014 | F47: 4 | G47: 2860 | H47: 14.3 | I47: 9804.08 | J47: Completed | K47: Mumbai | L47: 0 | M47: TRUE | N47: Sports | O47: Retail | P47: 35 | Q47: South | R47: 2028
A48: ORD-01858 | B48: 45652 | C48: CUST-0044 | D48: PROD-058 | E48: R027 | F48: 3 | G48: 2400 | H48: 20.7 | I48: 5709.6 | J48: Completed | K48: Hyderabad | L48: 0 | M48: TRUE | N48: Sports | O48: SMB | P48: 29 | Q48: West | R48: 974
A49: ORD-01853 | B49: 45650 | C49: CUST-0277 | D49: PROD-009 | E49: R017 | F49: 5 | G49: 1220 | H49: 18.7 | I49: 4959.3 | J49: Completed | K49: Chennai | L49: 0 | M49: TRUE | N49: Electronics | O49: Corporate | P49: 34 | Q49: East | R49: 517
A50: ORD-01852 | B50: 45605 | C50: CUST-0008 | D50: PROD-026 | E50: R010 | F50: 6 | G50: 4070 | H50: 28.9 | I50: 17362.62 | J50: Completed | K50: Pune | L50: 0 | M50: TRUE | N50: Grocery | O50: SMB | P50: 39 | Q50: South | R50: 2027
A51: ORD-01849 | B51: 45569 | C51: CUST-0217 | D51: PROD-039 | E51: R017 | F51: 7 | G51: 4610 | H51: 0.9 | I51: 31979.57 | J51: Completed | K51: Pune | L51: 0 | M51: TRUE | N51: Home | O51: SMB | P51: 59 | Q51: East | R51: 1850
A52: ORD-01841 | B52: 45605 | C52: CUST-0286 | D52: PROD-036 | E52: R025 | F52: 3 | G52: 3250 | H52: 19.6 | I52: 7839 | J52: Pending | K52: Delhi | L52: 0 | M52: TRUE | N52: Home | O52: Retail | P52: 62 | Q52: West | R52: 1556
A53: ORD-01837 | B53: 45647 | C53: CUST-0174 | D53: PROD-017 | E53: R006 | F53: 2 | G53: 2510 | H53: 28.2 | I53: 3604.36 | J53: Completed | K53: Pune | L53: 0 | M53: FALSE | N53: Apparel | O53: Retail | P53: 54 | Q53: North | R53: 1075
A54: ORD-01834 | B54: 45593 | C54: CUST-0242 | D54: PROD-017 | E54: R020 | F54: 4 | G54: 2510 | H54: 23.2 | I54: 7710.72 | J54: Completed | K54: Chennai | L54: 0 | M54: FALSE | N54: Apparel | O54: SMB | P54: 59 | Q54: East | R54: 1075
A55: ORD-01832 | B55: 45633 | C55: CUST-0223 | D55: PROD-055 | E55: R004 | F55: 6 | G55: 2860 | H55: 10.5 | I55: 15358.2 | J55: Cancelled | K55: Bengaluru | L55: 0 | M55: TRUE | N55: Sports | O55: Retail | P55: 46 | Q55: North | R55: 2028
A56: ORD-00053 | B56: 45616 | C56: CUST-0180 | D56: PROD-027 | E56: R013 | F56: 5 | G56: 3780 | H56: 18.5 | I56: 15403.5 | J56: Completed | K56: Chennai | L56: 0 | M56: TRUE | N56: Grocery | O56: Retail | P56: 36 | Q56: South | R56: 2436
... A184: ORD-01435 | B184: 45598 | C184: CUST-0130 | D184: PROD-018 | E184: R002 | F184: 5 | G184: 3560 | H184: 19.4 | I184: 14346.8 | J184: Pending | K184: Bengaluru | L184: 0 | M184: TRUE | N184: Apparel | O184: Corporate | P184: 41 | Q184: North | R184: 2629
...

Sheet Sheet2
A3: Sum of final_amount | B3: Column Labels
A4: Row Labels | B4: R001 | C4: R002 | D4: R003 | E4: R004 | F4: R005 | G4: R006 | H4: R007 | I4: R008 | J4: R009 | K4: R010 | L4: R011 | M4: R012 | N4: R013 | O4: R014 | P4: R015 | Q4: R016 | R4: R017 | S4: R018 | T4: R019 | U4: R020 | V4: R021 | W4: R022 | X4: R023 | Y4: R024 | Z4: R025 | AA4: R026 | AB4: R027 | AC4: R028 | AD4: R029 | AE4: R030 | AF4: Grand Total
A5: Jan | B5: 43650.56 | C5: 51707.32 | D5: 54307 | E5: 57892.11 | F5: 70665.51 | G5: 84968.56 | H5: 92029.91 | I5: 61557.02 | J5: 125547.54 | K5: 43078.21 | L5: 88791.72 | M5: 70680.03 | N5: 51609.12 | O5: 87497.74 | P5: 118901.06 | Q5: 62195.84 | R5: 73856.39 | S5: 101638.5 | T5: 30895.18 | U5: 41744.44 | V5: 2689.92 | W5: 158207.84 | X5: 54606.06 | Y5: 24937.08 | Z5: 56041.84 | AA5: 12767.82 | AB5: 77569.16 | AC5: 36574 | AD5: 45369.15 | AE5: 59170.81 | AF5: 1941147.4
A6: Feb | B6: 127005.17 | C6: 125187.78 | D6: 32452 | E6: 58818.56 | F6: 57914.81 | G6: 34581.99 | H6: 130276.04 | I6: 23463.3 | J6: 25935.55 | K6: 74555.64 | L6: 112894.06 | M6: 110195.46 | N6: 139218.08 | O6: 79488 | P6: 89654.68 | Q6: 90583.24 | R6: 27297.84 | S6: 121362.44 | T6: 97513.34 | U6: 13855.82 | V6: 104662.05 | W6: 46819.11 | X6: 120382.87 | Y6: 97833.74 | Z6: 43978.47 | AA6: 18592.26 | AB6: 80384.53 | AC6: 63178.48 | AD6: 142134.07 | AE6: 17274.29 | AF6: 2307493.7
A7: Mar | B7: 58208.49 | C7: 53533 | D7: 107489.23 | E7: 14394.38 | F7: 85853.43 | G7: 145435.13 | H7: 105489.83 | I7: 164615.05 | J7: 19130.39 | L7: 77891.76 | M7: 20450.24 | N7: 80024.44 | O7: 85611.84 | P7: 67837.49 | Q7: 153834.45 | R7: 120293.66 | S7: 51595.62 | T7: 68954.54 | U7: 215416.3 | V7: 100685.62 | W7: 51327.36 | X7: 82920.6 | Y7: 63984.05 | Z7: 130752.95 | AA7: 66759.36 | AB7: 36563.8 | AC7: 65497.58 | AD7: 63730.97 | AE7: 122041.06 | AF7: 2480322.6
A8: Apr | B8: 33643.48 | C8: 46286.92 | D8: 96349.86 | E8: 23036.54 | F8: 46025.56 | G8: 170939.91 | H8: 48536.18 | I8: 12044.56 | J8: 74565.16 | K8: 41398.06 | L8: 30549.1 | M8: 24950.8 | N8: 41420.61 | O8: 101517.17 | P8: 107626.6 | Q8: 75094.84 | R8: 32212.65 | S8: 210613.93 | T8: 112510.04 | U8: 49921.2 | V8: 71054.8 | W8: 93303.02 | X8: 216421.52 | Y8: 56736.5 | Z8: 49945.92 | AA8: 131132.88 | AB8: 78106.28 | AC8: 45577.73 | AD8: 124581.45 | AE8: 36350.86 | AF8: 2282454.1
A9: May | B9: 44809.66 | C9: 89794.86 | D9: 139257.72 | E9: 140739.8 | F9: 67702.82 | G9: 78322.48 | H9: 41157.84 | I9: 67200.57 | J9: 100231.54 | K9: 83732.94 | L9: 10392.16 | M9: 37183.63 | N9: 80787.31 | O9: 154170.2 | P9: 146185.96 | Q9: 67937.96 | R9: 113791.15 | S9: 173129.47 | T9: 58746.86 | U9: 182980.03 | V9: 56143.78 | W9: 8802.79 | X9: 40444.23 | Y9: 125217.67 | Z9: 59507.42 | AA9: 30080.4 | AB9: 85103.46 | AC9: 68897.65 | AD9: 180359.49 | AE9: 47579.17 | AF9: 2580391
A10: Jun | B10: 82789.95 | C10: 82753.37 | D10: 37966.09 | E10: 42388.12 | F10: 113205.32 | G10: 191251.6 | H10: 58895.11 | I10: 82481.44 | J10: 69794.65 | K10: 29458.16 | L10: 45625.44 | M10: 59218.28 | N10: 33836.58 | O10: 15951.6 | P10: 12840.4 | Q10: 55791.51 | R10: 73782.34 | S10: 117809.47 | T10: 107491.78 | U10: 90724.13 | V10: 65924.82 | W10: 61415.64 | X10: 102315.15 | Y10: 53450.71 | Z10: 66753.66 | AA10: 19115.52 | AB10: 49268.73 | AC10: 47140.72 | AD10: 29011.88 | AE10: 67486.9 | AF10: 1965939.1
A11: Jul | B11: 28761.2 | C11: 62949.74 | D11: 185921.75 | E11: 7823.48 | F11: 20649.35 | G11: 38479.32 | H11: 11528.24 | I11: 75853.47 | J11: 99012.62 | K11: 96008.48 | L11: 31373.22 | M11: 75017.78 | N11: 32733.74 | O11: 74760.15 | P11: 51083.42 | Q11: 70547.11 | R11: 4516.7 | S11: 41039.88 | T11: 72372.48 | U11: 28955.71 | V11: 72167.3 | W11: 210918.24 | X11: 89062.99 | Y11: 58773.84 | Z11: 140235.22 | AA11: 13927.63 | AB11: 32250.52 | AC11: 88182.8 | AD11: 60836.13 | AE11: 89271.18 | AF11: 1965013.7
A12: Aug | B12: 92676.92 | C12: 134500.5 | D12: 114656.27 | E12: 55975.34 | F12: 15060.28 | G12: 61857.9 | H12: 70196.8 | I12: 61043.44 | J12: 116575.85 | K12: 111335.79 | L12: 129473.96 | M12: 115185.59 | N12: 70557.86 | O12: 113977.94 | P12: 114985.86 | Q12: 119357.27 | R12: 88015.95 | S12: 26814.3 | T12: 20666.8 | U12: 107718.33 | V12: 44212.2 | W12: 81133.64 | X12: 50585.6 | Y12: 66015.24 | Z12: 61143.74 | AA12: 89359.82 | AB12: 18606.83 | AC12: 168231.25 | AD12: 134005.79 | AE12: 74000.9 | AF12: 2527928
A13: Sep | B13: 88884.34 | C13: 91647.29 | D13: 69896.72 | E13: 46944.28 | F13: 81963.69 | G13: 76627.83 | H13: 52194.15 | I13: 49404.64 | J13: 98466.52 | K13: 146100.57 | L13: 88472.06 | M13: 104717.03 | N13: 63389.33 | O13: 45673.51 | P13: 92815.3 | Q13: 34105.56 | R13: 75893.02 | S13: 29070.76 | T13: 34590.78 | U13: 57555.72 | V13: 108409.59 | W13: 87991.22 | X13: 50462.58 | Y13: 16909.74 | Z13: 121716.58 | AA13: 26249.42 | AB13: 133645.8 | AC13: 44209.14 | AD13: 18360.24 | AE13: 26448.21 | AF13: 2062815.6
A14: Oct | B14: 37753.9 | C14: 35751.81 | D14: 29309.98 | E14: 43456.18 | F14: 99252.77 | G14: 52942.27 | H14: 57313.75 | I14: 26620.46 | J14: 107648.92 | K14: 64630.99 | L14: 55503.48 | M14: 89150.85 | N14: 46714.58 | O14: 80097.18 | P14: 119179.18 | Q14: 55604.09 | R14: 75670.28 | S14: 109087.31 | T14: 152548.56 | U14: 23378.26 | V14: 42203.75 | W14: 73388.56 | X14: 13975.5 | Y14: 82877.57 | Z14: 8289.03 | AA14: 79217.4 | AB14: 110709.75 | AC14: 137494.43 | AD14: 27441.88 | AE14: 40669.76 | AF14: 1977882.4
A15: Nov | B15: 72215.41 | C15: 158277.82 | D15: 106760.75 | E15: 38491.18 | F15: 55570.99 | G15: 81500.24 | H15: 130208.9 | I15: 64537.26 | J15: 30954.96 | K15: 119201.57 | L15: 64240.8 | M15: 69152.06 | N15: 108112.07 | O15: 50971.92 | P15: 97394.65 | Q15: 26689.96 | R15: 23417.13 | S15: 84868.64 | T15: 96634.5 | U15: 68985.01 | V15: 53126.1 | W15: 76504.66 | X15: 59984.34 | Y15: 68084.65 | Z15: 103237.54 | AA15: 28769.67 | AB15: 110369.59 | AC15: 64459.77 | AD15: 65290.45 | AE15: 119624.49 | AF15: 2297637.1
A16: Dec | B16: 79450.52 | C16: 47673.25 | D16: 12325.54 | E16: 59066.32 | F16: 68580.8 | G16: 121741.5 | H16: 57922.93 | I16: 172732.12 | J16: 46691.02 | K16: 70844.79 | M16: 125492.57 | N16: 63120.66 | O16: 105996.29 | P16: 73235.58 | Q16: 2821.88 | R16: 71637.3 | S16: 45259.32 | T16: 118258.66 | U16: 24872.76 | V16: 40227.24 | W16: 119758.46 | X16: 102626.04 | Y16: 104737.79 | Z16: 59696.52 | AA16: 60332.9 | AB16: 104514.17 | AC16: 51024.5 | AD16: 125575.3 | AE16: 47706.74 | AF16: 2183923.5
A17: Grand Total | B17: 789849.6 | C17: 980063.66 | D17: 986692.91 | E17: 589026.29 | F17: 782445.33 | G17: 1138648.7 | H17: 855749.68 | I17: 861553.33 | J17: 914554.72 | K17: 880345.2 | L17: 735207.76 | M17: 901394.32 | N17: 811524.38 | O17: 995713.54 | P17: 1091740.2 | Q17: 814563.71 | R17: 780384.41 | S17: 1112289.6 | T17: 971183.52 | U17: 906107.71 | V17: 761507.17 | W17: 1069570.5 | X17: 983787.48 | Y17: 819558.58 | Z17: 901298.89 | AA17: 576305.08 | AB17: 917092.62 | AC17: 880468.05 | AD17: 1016696.8 | AE17: 747624.37 | AF17: 26572948

Sheet Orders
A1: order_id | B1: order_date | C1: customer_id | D1: product_id | E1: sales_rep_id | F1: quantity | G1: unit_price | H1: discount_pct | I1: final_amount | J1: payment_status | K1: ship_city | L1: dup_flag | M1: is_active | N1: category | O1: segment | P1: age | Q1: region | R1: unit_cost
A2: ORD-00001 | B2: 45549 | C2: CUST-0243 | D2: PROD-014 | E2: R007 | F2: 8 | G2: 3620 | H2: 15.4 | I2: 24500.16 | J2: Completed | K2: Pune | L2: =IF(COUNTIF(A$2:A2, A2)=1, IF(COUNTIF(A$2:A$2001, A2)>1, 1, 0), 0) -> 0 | M2: =VLOOKUP(D2, Products!A$2:F$61, 6, FALSE) -> TRUE | N2: =VLOOKUP(D2, Products!A$2:C$61, 3, FALSE) -> Apparel | O2: =VLOOKUP(C2, Customers!A$2:E$301, 5, FALSE) -> SMB | P2: =VLOOKUP(C2, Customers!A$2:C$301, 3, FALSE) -> 44 | Q2: =VLOOKUP(E2, Sales_Reps!A$2:C$31, 3, FALSE) -> North | R2: =VLOOKUP(D2, Products!A$2:D$61, 4, FALSE) -> 2509
A3: ORD-00002 | B3: 45340 | C3: CUST-0202 | D3: PROD-020 | E3: R005 | F3: 2 | G3: 820 | H3: 10.8 | I3: 1462.88 | J3: Pending | K3: Chennai | L3: =IF(COUNTIF(A$2:A3, A3)=1, IF(COUNTIF(A$2:A$2001, A3)>1, 1, 0), 0) -> 0 | M3: =VLOOKUP(D3, Products!A$2:F$61, 6, FALSE) -> TRUE | N3: =VLOOKUP(D3, Products!A$2:C$61, 3, FALSE) -> Apparel | O3: =VLOOKUP(C3, Customers!A$2:E$301, 5, FALSE) -> Retail | P3: =VLOOKUP(C3, Customers!A$2:C$301, 3, FALSE) -> 39 | Q3: =VLOOKUP(E3, Sales_Reps!A$2:C$31, 3, FALSE) -> North | R3: =VLOOKUP(D3, Products!A$2:D$61, 4, FALSE) -> 391
A4: ORD-00003 | B4: 45371 | C4: CUST-0098 | D4: PROD-053 | E4: R014 | F4: 8 | G4: 470 | H4: 3.3 | I4: 3635.92 | J4: Pending | K4: Delhi | L4: =IF(COUNTIF(A$2:A4, A4)=1, IF(COUNTIF(A$2:A$2001, A4)>1, 1, 0), 0) -> 0 | M4: =VLOOKUP(D4, Products!A$2:F$61, 6, FALSE) -> FALSE | N4: =VLOOKUP(D4, Products!A$2:C$61, 3, FALSE) -> Sports | O4: =VLOOKUP(C4, Customers!A$2:E$301, 5, FALSE) -> Retail | P4: =VLOOKUP(C4, Customers!A$2:C$301, 3, FALSE) -> 52 | Q4: =VLOOKUP(E4, Sales_Reps!A$2:C$31, 3, FALSE) -> South | R4: =VLOOKUP(D4, Products!A$2:D$61, 4, FALSE) -> 302
A5: ORD-00004 | B5: 45413 | C5: CUST-0071 | D5: PROD-028 | E5: R006 | F5: 1 | G5: 3660 | H5: 15.7 | I5: 3085.38 | J5: Completed | K5: Delhi | L5: =IF(COUNTIF(A$2:A5, A5)=1, IF(COUNTIF(A$2:A$2001, A5)>1, 1, 0), 0) -> 0 | M5: =VLOOKUP(D5, Products!A$2:F$61, 6, FALSE) -> FALSE | N5: =VLOOKUP(D5, Products!A$2:C$61, 3, FALSE) -> Grocery | O5: =VLOOKUP(C5, Customers!A$2:E$301, 5, FALSE) -> Corporate | P5: =VLOOKUP(C5, Customers!A$2:C$301, 3, FALSE) -> 46 | Q5: =VLOOKUP(E5, Sales_Reps!A$2:C$31, 3, FALSE) -> North | R5: =VLOOKUP(D5, Products!A$2:D$61, 4, FALSE) -> 2214
A6: ORD-00005 | B6: 45611 | C6: CUST-0180 | D6: PROD-012 | E6: R008 | F6: 1 | G6: 3160 | H6: 26 | I6: 2338.4 | J6: Completed | K6: Chennai | L6: =IF(COUNTIF(A$2:A6, A6)=1, IF(COUNTIF(A$2:A$2001, A6)>1, 1, 0), 0) -> 0 | M6: =VLOOKUP(D6, Products!A$2:F$61, 6, FALSE) -> TRUE | N6: =VLOOKUP(D6, Products!A$2:C$61, 3, FALSE) -> Apparel | O6: =VLOOKUP(C6, Customers!A$2:E$301, 5, FALSE) -> Retail | P6: =VLOOKUP(C6, Customers!A$2:C$301, 3, FALSE) -> 36 | Q6: =VLOOKUP(E6, Sales_Reps!A$2:C$31, 3, FALSE) -> North | R6: =VLOOKUP(D6, Products!A$2:D$61, 4, FALSE) -> 1886
A7: ORD-00006 | B7: 45406 | C7: CUST-0275 | D7: PROD-032 | E7: R025 | F7: 4 | G7: 370 | H7: 29 | I7: 1050.8 | J7: Completed | K7: Mumbai | L7: =IF(COUNTIF(A$2:A7, A7)=1, IF(COUNTIF(A$2:A$2001, A7)>1, 1, 0), 0) -> 0 | M7: =VLOOKUP(D7, Products!A$2:F$61, 6, FALSE) -> TRUE | N7: =VLOOKUP(D7, Products!A$2:C$61, 3, FALSE) -> Home | O7: =VLOOKUP(C7, Customers!A$2:E$301, 5, FALSE) -> Retail | P7: =VLOOKUP(C7, Customers!A$2:C$301, 3, FALSE) -> 36 | Q7: =VLOOKUP(E7, Sales_Reps!A$2:C$31, 3, FALSE) -> West | R7: =VLOOKUP(D7, Products!A$2:D$61, 4, FALSE) -> 288
A8: ORD-00007 | B8: 45455 | C8: CUST-0293 | D8: PROD-057 | E8: R024 | F8: 3 | G8: 960 | H8: 5.8 | I8: 2712.96 | J8: Completed | K8: Bengaluru | L8: =IF(COUNTIF(A$2:A8, A8)=1, IF(COUNTIF(A$2:A$2001, A8)>1, 1, 0), 0) -> 0 | M8: =VLOOKUP(D8, Products!A$2:F$61, 6, FALSE) -> TRUE | N8: =VLOOKUP(D8, Products!A$2:C$61, 3, FALSE) -> Sports | O8: =VLOOKUP(C8, Customers!A$2:E$301, 5, FALSE) -> Retail | P8: =VLOOKUP(C8, Customers!A$2:C$301, 3, FALSE) -> 27 | Q8: =VLOOKUP(E8, Sales_Reps!A$2:C$31, 3, FALSE) -> West | R8: =VLOOKUP(D8, Products!A$2:D$61, 4, FALSE) -> 705
A9: ORD-00008 | B9: 45617 | C9: CUST-0281 | D9: PROD-007 | E9: R019 | F9: 8 | G9: 1430 | H9: 2.4 | I9: 11165.44 | J9: Completed | K9: Bengaluru | L9: =IF(COUNTIF(A$2:A9, A9)=1, IF(COUNTIF(A$2:A$2001, A9)>1, 1, 0), 0) -> 0 | M9: =VLOOKUP(D9, Products!A$2:F$61, 6, FALSE) -> TRUE | N9: =VLOOKUP(D9, Products!A$2:C$61, 3, FALSE) -> Electronics | O9: =VLOOKUP(C9, Customers!A$2:E$301, 5, FALSE) -> Corporate | P9: =VLOOKUP(C9, Customers!A$2:C$301, 3, FALSE) -> 57 | Q9: =VLOOKUP(E9, Sales_Reps!A$2:C$31, 3, FALSE) -> East | R9: =VLOOKUP(D9, Products!A$2:D$61, 4, FALSE) -> 861
A10: ORD-00009 | B10: 45549 | C10: CUST-0260 | D10: PROD-038 | E10: R008 | F10: 3 | G10: 5490 | H10: 14.2 | I10: 14131.26 | J10: Completed | K10: Bengaluru | L10: =IF(COUNTIF(A$2:A10, A10)=1, IF(COUNTIF(A$2:A$2001, A10)>1, 1, 0), 0) -> 0 | M10: =VLOOKUP(D10, Products!A$2:F$61, 6, FALSE) -> TRUE | N10: =VLOOKUP(D10, Products!A$2:C$61, 3, FALSE) -> Home | O10: =VLOOKUP(C10, Customers!A$2:E$301, 5, FALSE) -> Retail | P10: =VLOOKUP(C10, Customers!A$2:C$301, 3, FALSE) -> 42 | Q10: =VLOOKUP(E10, Sales_Reps!A$2:C$31, 3, FALSE) -> North | R10: =VLOOKUP(D10, Products!A$2:D$61, 4, FALSE) -> 2549
A11: ORD-00010 | B11: 45396 | C11: CUST-0147 | D11: PROD-030 | E11: R028 | F11: 3 | G11: 970 | H11: 1.2 | I11: 2875.08 | J11: Completed | K11: Pune | L11: =IF(COUNTIF(A$2:A11, A11)=1, IF(COUNTIF(A$2:A$2001, A11)>1, 1, 0), 0) -> 0 | M11: =VLOOKUP(D11, Products!A$2:F$61, 6, FALSE) -> TRUE | N11: =VLOOKUP(D11, Products!A$2:C$61, 3, FALSE) -> Grocery | O11: =VLOOKUP(C11, Customers!A$2:E$301, 5, FALSE) -> Retail | P11: =VLOOKUP(C11, Customers!A$2:C$301, 3, FALSE) -> 56 | Q11: =VLOOKUP(E11, Sales_Reps!A$2:C$31, 3, FALSE) -> West | R11: =VLOOKUP(D11, Products!A$2:D$61, 4, FALSE) -> 434
A12: ORD-00011 | B12: 45560 | C12: CUST-0204 | D12: PROD-024 | E12: R010 | F12: 7 | G12: 2270 | H12: 7.1 | I12: 14761.81 | J12: Pending | K12: Hyderabad | L12: =IF(COUNTIF(A$2:A12, A12)=1, IF(COUNTIF(A$2:A$2001, A12)>1, 1, 0), 0) -> 0 | M12: =VLOOKUP(D12, Products!A$2:F$61, 6, FALSE) -> TRUE | N12: =VLOOKUP(D12, Products!A$2:C$61, 3, FALSE) -> Grocery | O12: =VLOOKUP(C12, Customers!A$2:E$301, 5, FALSE) -> Retail | P12: =VLOOKUP(C12, Customers!A$2:C$301, 3, FALSE) -> 60 | Q12: =VLOOKUP(E12, Sales_Reps!A$2:C$31, 3, FALSE) -> South | R12: =VLOOKUP(D12, Products!A$2:D$61, 4, FALSE) -> 1203
A13: ORD-00012 | B13: 45332 | C13: CUST-0147 | D13: PROD-010 | E13: R024 | F13: 9 | G13: 2640 | H13: 21.7 | I13: 18604.08 | J13: Completed | K13: Pune | L13: =IF(COUNTIF(A$2:A13, A13)=1, IF(COUNTIF(A$2:A$2001, A13)>1, 1, 0), 0) -> 0 | M13: =VLOOKUP(D13, Products!A$2:F$61, 6, FALSE) -> TRUE | N13: =VLOOKUP(D13, Products!A$2:C$61, 3, FALSE) -> Electronics | O13: =VLOOKUP(C13, Customers!A$2:E$301, 5, FALSE) -> Retail | P13: =VLOOKUP(C13, Customers!A$2:C$301, 3, FALSE) -> 56 | Q13: =VLOOKUP(E13, Sales_Reps!A$2:C$31, 3, FALSE) -> West | R13: =VLOOKUP(D13, Products!A$2:D$61, 4, FALSE) -> 1149
... A2001: ORD-02000 | B2001: 45325 | C2001: CUST-0238 | D2001: PROD-034 | E2001: R023 | F2001: 6 | G2001: 5080 | H2001: 28.1 | I2001: 21915.12 | J2001: Completed | K2001: Delhi | L2001: =IF(COUNTIF(A$2:A2001, A2001)=1, IF(COUNTIF(A$2:A$2001, A2001)>1, 1, 0), 0) -> 0 | M2001: =VLOOKUP(D2001, Products!A$2:F$61, 6, FALSE) -> TRUE | N2001: =VLOOKUP(D2001, Products!A$2:C$61, 3, FALSE) -> Home | O2001: =VLOOKUP(C2001, Customers!A$2:E$301, 5, FALSE) -> Retail | P2001: =VLOOKUP(C2001, Customers!A$2:C$301, 3, FALSE) -> 49 | Q2001: =VLOOKUP(E2001, Sales_Reps!A$2:C$31, 3, FALSE) -> East | R2001: =VLOOKUP(D2001, Products!A$2:D$61, 4, FALSE) -> 2459

Sheet Customers
A1: customer_id | B1: customer_name | C1: age | D1: city | E1: segment | F1: signup_date
A2: CUST-0001 | B2: Amit Agarwal | C2: 36 | D2: Pune | E2: Retail | F2: 44819
A3: CUST-0002 | B3: Vihaan Malhotra | C3: 42 | D3: Pune | E3: Corporate | F3: 44984
A4: CUST-0003 | B4: Navya Malhotra | C4: 33 | D4: Mumbai | E4: Retail | F4: 44059
A5: CUST-0004 | B5: Aaradhya Mehta | C5: 53 | D5: delhi | E5: Retail | F5: 44054
A6: CUST-0005 | B6: Myra Malhotra | C6: 52 | D6: Chennai | E6: Corporate | F6: 45037
A7: CUST-0006 | B7: Shaurya Iyer | C7: 44 | D7: Pune | E7: SMB | F7: 44302
A8: CUST-0007 | B8: Dhruv Joshi | C8: 47 | D8: Bengaluru | E8: Retail | F8: 44498
A9: CUST-0008 | B9: Kavita Malhotra | C9: 39 | D9: Pune | E9: SMB | F9: 45162
A10: CUST-0009 | B10: Neha Malhotra | C10: 61 | D10: Mumbai | E10: Retail | F10: 44343
A11: CUST-0010 | B11: Aaradhya Gupta | C11: 61 | D11: Mumbai | E11: SMB | F11: 44975
A12: CUST-0011 | B12: Diya Menon | C12: 41 | D12: Chennai | E12: Corporate | F12: 44821
A13: CUST-0012 | B13: Prisha Desai | C13: 43 | D13: Pune | E13: Retail | F13: 44718
... A301: CUST-0300 | B301: Rohit Nair | C301: 38 | D301: Mumbai | E301: Retail | F301: 43932

Sheet Products
A1: product_id | B1: product_name | C1: category | D1: unit_cost | E1: unit_price | F1: is_active | G1: west_revenue
A2: PROD-001 | B2: Smartphone Pro | C2: Electronics | D2: 2405 | E2: 5330 | F2: TRUE | G2: =SUMIFS(Orders!I$2:I$2001, Orders!D$2:D$2001, A2, Orders!Q$2:Q$2001, "West") -> 155358.84
A3: PROD-002 | B3: Wireless Earbuds | C3: Electronics | D3: 1052 | E3: 2600 | F3: TRUE | G3: =SUMIFS(Orders!I$2:I$2001, Orders!D$2:D$2001, A3, Orders!Q$2:Q$2001, "West") -> 105284.4
A4: PROD-003 | B4: Smart Watch | C4: Electronics | D4: 1665 | E4: 3570 | F4: TRUE | G4: =SUMIFS(Orders!I$2:I$2001, Orders!D$2:D$2001, A4, Orders!Q$2:Q$2001, "West") -> 248025.75
A5: PROD-004 | B5: Laptop Bag | C5: Electronics | D5: 1559 | E5: 3870 | F5: TRUE | G5: =SUMIFS(Orders!I$2:I$2001, Orders!D$2:D$2001, A5, Orders!Q$2:Q$2001, "West") -> 198124.65
A6: PROD-005 | B6: Power Bank | C6: Electronics | D6: 128 | E6: 300 | F6: TRUE | G6: =SUMIFS(Orders!I$2:I$2001, Orders!D$2:D$2001, A6, Orders!Q$2:Q$2001, "West") -> 7449.9
A7: PROD-006 | B7: Bluetooth Speaker | C7: Electronics | D7: 2865 | E7: 3970 | F7: TRUE | G7: =SUMIFS(Orders!I$2:I$2001, Orders!D$2:D$2001, A7, Orders!Q$2:Q$2001, "West") -> 100869.76
A8: PROD-007 | B8: USB-C Cable | C8: Electronics | D8: 861 | E8: 1430 | F8: TRUE | G8: =SUMIFS(Orders!I$2:I$2001, Orders!D$2:D$2001, A8, Orders!Q$2:Q$2001, "West") -> 38531.35
A9: PROD-008 | B9: Wireless Mouse | C9: Electronics | D9: 1259 | E9: 2660 | F9: FALSE | G9: =SUMIFS(Orders!I$2:I$2001, Orders!D$2:D$2001, A9, Orders!Q$2:Q$2001, "West") -> 7807.1
A10: PROD-009 | B10: Mechanical Keyboard | C10: Electronics | D10: 517 | E10: 1220 | F10: TRUE | G10: =SUMIFS(Orders!I$2:I$2001, Orders!D$2:D$2001, A10, Orders!Q$2:Q$2001, "West") -> 64207.38
A11: PROD-010 | B11: Tablet Stand | C11: Electronics | D11: 1149 | E11: 2640 | F11: TRUE | G11: =SUMIFS(Orders!I$2:I$2001, Orders!D$2:D$2001, A11, Orders!Q$2:Q$2001, "West") -> 67393.92
A12: PROD-011 | B12: Cotton T-Shirt | C12: Apparel | D12: 1748 | E12: 3450 | F12: TRUE | G12: =SUMIFS(Orders!I$2:I$2001, Orders!D$2:D$2001, A12, Orders!Q$2:Q$2001, "West") -> 145224.3
A13: PROD-012 | B13: Denim Jeans | C13: Apparel | D13: 1886 | E13: 3160 | F13: TRUE | G13: =SUMIFS(Orders!I$2:I$2001, Orders!D$2:D$2001, A13, Orders!Q$2:Q$2001, "West") -> 121770.6
... A61: PROD-060 | B61: Gym Gloves | C61: Sports | D61: 147 | E61: 190 | F61: TRUE | G61: =SUMIFS(Orders!I$2:I$2001, Orders!D$2:D$2001, A61, Orders!Q$2:Q$2001, "West") -> 7838.26

Sheet Sales_Reps
A1: rep_id | B1: rep_name | C1: region | D1: hire_date | E1: team_lead_id | F1: total_revenue | G1: rank
A2: R001 | B2: Rajesh Malhotra | C2: North | D2: 44207 | F2: =SUMIF(Orders!E$2:E$2001, A2, Orders!I$2:I$2001) -> 789849.6 | G2: =_xlfn.RANK.EQ(F2, F$2:F$31) -> 23
A3: R002 | B3: Sunita Malhotra | C3: North | D3: 44028 | F3: =SUMIF(Orders!E$2:E$2001, A3, Orders!I$2:I$2001) -> 980063.66 | G3: =_xlfn.RANK.EQ(F3, F$2:F$31) -> 9
A4: R003 | B4: Amit Singh | C4: North | D4: 43651 | F4: =SUMIF(Orders!E$2:E$2001, A4, Orders!I$2:I$2001) -> 986692.91 | G4: =_xlfn.RANK.EQ(F4, F$2:F$31) -> 7
A5: R004 | B5: Priya Singh | C5: North | D5: 44907 | F5: =SUMIF(Orders!E$2:E$2001, A5, Orders!I$2:I$2001) -> 589026.29 | G5: =_xlfn.RANK.EQ(F5, F$2:F$31) -> 29
A6: R005 | B6: Vikram Patel | C6: North | D6: 43588 | E6: R001 | F6: =SUMIF(Orders!E$2:E$2001, A6, Orders!I$2:I$2001) -> 782445.33 | G6: =_xlfn.RANK.EQ(F6, F$2:F$31) -> 24
A7: R006 | B7: Neha Desai | C7: North | D7: 44131 | E7: R001 | F7: =SUMIF(Orders!E$2:E$2001, A7, Orders!I$2:I$2001) -> 1138648.7 | G7: =_xlfn.RANK.EQ(F7, F$2:F$31) -> 1
A8: R007 | B8: Suresh Menon | C8: North | D8: 43493 | E8: R001 | F8: =SUMIF(Orders!E$2:E$2001, A8, Orders!I$2:I$2001) -> 855749.68 | G8: =_xlfn.RANK.EQ(F8, F$2:F$31) -> 19
A9: R008 | B9: Kavita Patel | C9: North | D9: 44693 | E9: R001 | F9: =SUMIF(Orders!E$2:E$2001, A9, Orders!I$2:I$2001) -> 861553.33 | G9: =_xlfn.RANK.EQ(F9, F$2:F$31) -> 18
A10: R009 | B10: Manoj Patel | C10: South | D10: 44804 | E10: R002 | F10: =SUMIF(Orders!E$2:E$2001, A10, Orders!I$2:I$2001) -> 914554.72 | G10: =_xlfn.RANK.EQ(F10, F$2:F$31) -> 12
A11: R010 | B11: Divya Rao | C11: South | D11: 43904 | E11: R002 | F11: =SUMIF(Orders!E$2:E$2001, A11, Orders!I$2:I$2001) -> 880345.2 | G11: =_xlfn.RANK.EQ(F11, F$2:F$31) -> 17
A12: R011 | B12: Anil Verma | C12: South | D12: 44622 | E12: R002 | F12: =SUMIF(Orders!E$2:E$2001, A12, Orders!I$2:I$2001) -> 735207.76 | G12: =_xlfn.RANK.EQ(F12, F$2:F$31) -> 28
A13: R012 | B13: Pooja Nair | C13: South | D13: 44890 | E13: R002 | F13: =SUMIF(Orders!E$2:E$2001, A13, Orders!I$2:I$2001) -> 901394.32 | G13: =_xlfn.RANK.EQ(F13, F$2:F$31) -> 14
A14: R013 | B14: Sanjay Kapoor | C14: South | D14: 45215 | E14: R002 | F14: =SUMIF(Orders!E$2:E$2001, A14, Orders!I$2:I$2001) -> 811524.38 | G14: =_xlfn.RANK.EQ(F14, F$2:F$31) -> 22
A15: R014 | B15: Ritu Menon | C15: South | D15: 44469 | E15: R002 | F15: =SUMIF(Orders!E$2:E$2001, A15, Orders!I$2:I$2001) -> 995713.54 | G15: =_xlfn.RANK.EQ(F15, F$2:F$31) -> 6
A16: R015 | B16: Deepak Shah | C16: South | D16: 45231 | E16: R002 | F16: =SUMIF(Orders!E$2:E$2001, A16, Orders!I$2:I$2001) -> 1091740.2 | G16: =_xlfn.RANK.EQ(F16, F$2:F$31) -> 3
A17: R016 | B17: Anjali Chopra | C17: South | D17: 43614 | E17: R002 | F17: =SUMIF(Orders!E$2:E$2001, A17, Orders!I$2:I$2001) -> 814563.71 | G17: =_xlfn.RANK.EQ(F17, F$2:F$31) -> 21
... A31: R030 | B31: Kiran Bhatt | C31: West | D31: 44506 | E31: R004 | F31: =SUMIF(Orders!E$2:E$2001, A31, Orders!I$2:I$2001) -> 747624.37 | G31: =_xlfn.RANK.EQ(F31, F$2:F$31) -> 27

Sheet Targets
A1: rep_id | B1: Jan-24 | C1: Feb-24 | D1: Mar-24 | E1: Apr-24 | F1: May-24 | G1: Jun-24 | H1: Jul-24 | I1: Aug-24 | J1: Sep-24 | K1: Oct-24 | L1: Nov-24 | M1: Dec-24
A2: R001 | B2: 231324 | C2: 171682 | D2: 234376 | E2: 326967 | F2: 350588 | G2: 385324 | H2: 307980 | I2: 327947 | J2: 181016 | K2: 374039 | L2: 212805 | M2: 405999
A3: R002 | B3: 438126 | C3: 346266 | D3: 329993 | E3: 370744 | F3: 294660 | G3: 341556 | H3: 151934 | I3: 223794 | J3: 438641 | K3: 344308 | L3: 296172 | M3: 304288
A4: R003 | B4: 358703 | C4: 320519 | D4: 327321 | E4: 298753 | F4: 254636 | G4: 351929 | H4: 264723 | I4: 216459 | J4: 391945 | K4: 362426 | L4: 289199 | M4: 301863
A5: R004 | B5: 389594 | C5: 376422 | D5: 324156 | E5: 420255 | F5: 409107 | G5: 269954 | H5: 179097 | I5: 370568 | J5: 387395 | K5: 243454 | L5: 232530 | M5: 201999
A6: R005 | B6: 436862 | C6: 391158 | D6: 340224 | E6: 170548 | F6: 229390 | G6: 349525 | H6: 154683 | I6: 320848 | J6: 354452 | K6: 377180 | L6: 342347 | M6: 183362
A7: R006 | B7: 348734 | C7: 358191 | D7: 250385 | E7: 219657 | F7: 249365 | G7: 435704 | H7: 260892 | I7: 250741 | J7: 358402 | K7: 379858 | L7: 213280 | M7: 224634
A8: R007 | B8: 280057 | C8: 330342 | D8: 336856 | E8: 227425 | F8: 233647 | G8: 307088 | H8: 370724 | I8: 440008 | J8: 406347 | K8: 217357 | L8: 299289 | M8: 214568
A9: R008 | B9: 252886 | C9: 206057 | D9: 318209 | E9: 411230 | F9: 448660 | G9: 171135 | H9: 305339 | I9: 432264 | J9: 294273 | K9: 371409 | L9: 284207 | M9: 437068
A10: R009 | B10: 268752 | C10: 393256 | D10: 310649 | E10: 246237 | F10: 271287 | G10: 314545 | H10: 406506 | I10: 334930 | J10: 348625 | K10: 408928 | L10: 243749 | M10: 418409
A11: R010 | B11: 384734 | C11: 156698 | D11: 283679 | E11: 276085 | F11: 409270 | G11: 285230 | H11: 304233 | I11: 178221 | J11: 284216 | K11: 287373 | L11: 229082 | M11: 298969
A12: R011 | B12: 186029 | C12: 151419 | D12: 253251 | E12: 379757 | F12: 204209 | G12: 179396 | H12: 378008 | I12: 182649 | J12: 267772 | K12: 350352 | L12: 358042 | M12: 359960
A13: R012 | B13: 352158 | C13: 251181 | D13: 321255 | E13: 300863 | F13: 241731 | G13: 393275 | H13: 313561 | I13: 283604 | J13: 429065 | K13: 194420 | L13: 254168 | M13: 389283
... A31: R030 | B31: 151584 | C31: 221679 | D31: 385157 | E31: 290386 | F31: 236041 | G31: 407985 | H31: 184446 | I31: 342894 | J31: 180344 | K31: 292917 | L31: 314858 | M31: 364057

Sheet Q1_Lookups
A1: Q1 - LOOKUP FUNCTIONS (25 marks total)
A2: VLOOKUP · INDEX-MATCH · Two-way lookup · Chain lookup · Approximate lookup · Self-join
A4: Q# | B4: Question | C4: Marks | D4: Hint | E4: Your Answer | F4: Format
A5: Q1.1 | B5: For order ORD-00234, what is the customer_id? | C5: 3 | D5: Simple VLOOKUP on Orders sheet. | E5: =VLOOKUP("ORD-00234",Orders!A:C,3,FALSE) -> CUST-0173 | F5: CUST-####
A6: Q1.2 | B6: For order ORD-00456, what is the product_name? (You will need to look up the product_id first, then find its name in Products.) | C6: 3 | D6: Two-step lookup, or nested VLOOKUP. | E6: =VLOOKUP(VLOOKUP("ORD-00456",Orders!A:D,4,FALSE),Products!A:B,2,FALSE) -> Dumbbells 5kg | F6: Text
A7: Q1.3 | B7: For order ORD-00987, what is the rep_name of the sales rep? Note: the rep_name is in a column that appears to the LEFT of what you might look up first. | C7: 3 | D7: VLOOKUP has directional limits - INDEX/MATCH does not. | E7: =INDEX(Sales_Reps!B:B,MATCH(VLOOKUP("ORD-00987",Orders!A:E,5,FALSE),Sales_Reps!A:A,0)) -> Nisha Menon | F7: Text
A8: Q1.4 | B8: From the Targets sheet, what is the target value for rep R012 in the month Mar-24? | C8: 4 | D8: Two-way lookup: row = rep_id, column = month. | E8: =INDEX(Targets!B:M,MATCH("R012",Targets!A:A,0),MATCH("Mar-24",Targets!B1:M1,0)) -> 321255 | F8: Whole number
A9: Q1.5 | B9: For order ORD-01500, what is the CATEGORY of the product ordered? (Chain: order → product_id → category) | C9: 4 | D9: Multi-hop lookup across sheets. | E9: =VLOOKUP(VLOOKUP("ORD-01500",Orders!A:D,4,FALSE),Products!A:C,3,FALSE) -> Electronics | F9: Text
A10: Q1.6 | B10: For order ORD-00789, which DISCOUNT SLAB does it fall in? Use the slab table below (rows 20-24). Slab breakpoints are the LOWER bound of each range. | C10: 3 | D10: Approximate-match VLOOKUP (sort ascending, TRUE / omit last arg). | E10: =VLOOKUP(VLOOKUP("ORD-00789",Orders!A:H,8,FALSE),$B$18:$C$21,2,TRUE) -> Bronze | F10: Text
A11: Q1.7 | B11: For order ORD-01234, in one cell produce the string: "<rep_name> (<sales_region>)" - e.g. "Amit Singh (South)". | C11: 3 | D11: Two lookups joined with & or CONCATENATE. | E11: =INDEX(Sales_Reps!B:B,MATCH(VLOOKUP("ORD-01234",Orders!A:E,5,FALSE),Sales_Reps!A:A,0)) & " (" & INDEX(Sales_Reps!C:C,MATCH(VLOOKUP("ORD-01234",Orders!A:E,5,FALSE),Sales_Reps!A:A,0)) & ")" -> Sanjay Kapoor (South) | F11: Text
A12: Q1.8 | B12: What is the rep_name of the TEAM LEAD for rep R017? (The Sales_Reps sheet has team_lead_id - you need to self-join to find that person's name.) | C12: 2 | D12: Look up the team_lead_id, then look up THAT id's rep_name. | E12: =INDEX(Sales_Reps!B:B,MATCH(INDEX(Sales_Reps!E:E,MATCH("R017",Sales_Reps!A:A,0)),Sales_Reps!A:A,0)) -> Amit Singh | F12: Text
B15: DISCOUNT SLAB REFERENCE TABLE (use for Q1.6)
B17: Discount % (Lower) | C17: Slab
B18: 0 | C18: Bronze
B19: 5 | C19: Silver
B20: 15 | C20: Gold
B21: 25 | C21: Platinum

Sheet Q2_Cleaning
A1: Q2 - DATA CLEANING & QUALITY DIAGNOSTICS (20 marks total)
A2: Duplicates · Whitespace · Case Inconsistency · Referential Integrity · Discontinued SKUs · Anomaly Patterns
A4: Q# | B4: Question | C4: Marks | D4: Hint | E4: Your Answer | F4: Format
A5: Q2.1 | B5: How many DUPLICATE rows exist in the Orders sheet (i.e., how many order_id values appear more than once)? Count each duplicate as ONE (not the extras). | C5: 3 | D5: COUNTIF > 1, then count. Watch what you're counting - rows or IDs. | E5: =SUM(Orders!L2:L2001) -> 20 | F5: Whole number
A6: Q2.2 | B6: How many customers in the Customers sheet have LEADING or TRAILING whitespace in their customer_name? | C6: 3 | D6: Compare LEN vs LEN(TRIM). Or use SUMPRODUCT with a boolean. | E6: {=SUMPRODUCT(--(LEN(Customers!B2:B301)<>LEN(TRIM(Customers!B2:B301))))} -> 15 | F6: Whole number
A7: Q2.3 | B7: The Customers sheet has some cities in inconsistent case (e.g., "mumbai", "MUMBAI", "Mumbai"). How many DISTINCT cities exist AFTER standardizing case? | C7: 3 | D7: Combine PROPER/UPPER with a de-dup count. SUMPRODUCT + 1/COUNTIF trick works. | E7: {=SUMPRODUCT(1/COUNTIF(Customers!D2:D301, Customers!D2:D301))} -> 6 | F7: Whole number
A8: Q2.4 | B8: How many orders reference a customer_id that DOES NOT EXIST in the Customers sheet? (Broken foreign key) | C8: 4 | D8: Use MATCH with ISNA/ISERROR, then count. | E8: {=SUMPRODUCT(--ISNA(MATCH(Orders!C2:C2001,Customers!A2:A301,0)))} -> 30 | F8: Whole number
A9: Q2.5 | B9: How many orders reference a product that is currently DISCONTINUED (is_active = FALSE in the Products sheet)? | C9: 3 | D9: VLOOKUP the is_active flag, then count where FALSE. | E9: =COUNTIF(Orders!M2:M2001, FALSE) -> 174 | F9: Whole number
A10: Q2.6 | B10: Find the "suspicious pattern": how many orders have payment_status = "Cancelled" AND a discount_pct > 20%? (This pattern often indicates promo abuse - a real-world diagnostic query.) | C10: 4 | D10: COUNTIFS with two criteria. | E10: =COUNTIFS(Orders!J2:J2001, "Cancelled", Orders!H2:H2001, ">20") -> 58 | F10: Whole number

Sheet Q3_Aggregation
A1: Q3 - CONDITIONAL AGGREGATION (25 marks total)
A2: SUMIFS · COUNTIFS · AVERAGEIFS · Nested IF logic · Multi-sheet aggregation · Top-N logic
A4: Q# | B4: Question | C4: Marks | D4: Hint | E4: Your Answer | F4: Format
A5: Q3.1 | B5: What is the TOTAL REVENUE (sum of final_amount) for orders in Q3 2024 (Jul-Sep) where ship_city is Mumbai? | C5: 4 | D5: SUMIFS with 3 conditions: date >= start, date <= end, city = Mumbai. Beware case issues. | E5: =SUMIFS(Orders!I2:I2001, Orders!B2:B2001, ">=2024-07-01", Orders!B2:B2001, "<=2024-09-30", Orders!K2:K2001, "Mumbai") -> 1217239 | F5: Currency
A6: Q3.2 | B6: How many orders have discount_pct > 15% AND payment_status = "Completed"? | C6: 3 | D6: COUNTIFS with two conditions. | E6: =COUNTIFS(Orders!H2:H2001, ">15", Orders!J2:J2001, "Completed") -> 723 | F6: Whole number
A7: Q3.3 | B7: What is the AVERAGE final_amount for orders where the product CATEGORY is "Electronics" AND the customer SEGMENT is "Corporate"? Note: Both fields come from OTHER sheets - you'll need helper columns. | C7: 5 | D7: Helper columns in Orders: VLOOKUP category from Products, VLOOKUP segment from Customers. Then AVERAGEIFS. | E7: =AVERAGEIFS(Orders!I2:I2001, Orders!N2:N2001, "Electronics", Orders!O2:O2001, "Corporate") -> 13981.402 | F7: Currency
A8: Q3.4 | B8: What is the COMBINED REVENUE of the TOP 3 reps by total revenue? (Sum of the 3 highest rep totals.) | C8: 4 | D8: Compute per-rep totals, then use SUMPRODUCT with LARGE, or sort and sum top 3. | E8: =LARGE(Sales_Reps!F2:F31, 1) + LARGE(Sales_Reps!F2:F31, 2) + LARGE(Sales_Reps!F2:F31, 3) -> 3342678.5 | F8: Currency
A9: Q3.5 | B9: For rep R015 in Nov-24: compute the actual revenue and compare to the target (from Targets sheet). Report the PERFORMANCE TIER using: <80% → "Below", 80-120% → "On Track", >120% → "Exceeds". Return only the tier text. | C9: 5 | D9: Nested IF (or IFS): compute actual/target ratio, then classify. | E9: =IF(SUMIFS(Orders!I2:I2001, Orders!E2:E2001, "R015", Orders!B2:B2001, ">=2024-11-01", Orders!B2:B2001, "<=2024-11-30") / VLOOKUP("R015", Targets!A2:M31, 12, FALSE) < 0.8, "Below", IF(SUMIFS(Orders!I2:I2001, Orders!E2:E2001, "R015", Orders!B2:B2001, ">=2024-11-01", Orders!B2:B2001, "<=2024-11-30") / VLOOKUP("R015", Targets!A2:M31, 12, FALSE) <= 1.2, "On Track", "Exceeds")) -> Below | F9: Text
A10: Q3.6 | B10: What is the TOTAL revenue from Corporate segment customers aged between 30 and 40 (both inclusive)? | C10: 4 | D10: Helper columns for age and segment. Then SUMIFS with numeric range. | E10: =SUMIFS(Orders!I2:I2001, Orders!O2:O2001, "Corporate", Orders!P2:P2001, ">=30", Orders!P2:P2001, "<=40") -> 982568.4 | F10: Currency

Sheet Q4_Pivot
A1: Q4 - PIVOT TABLES (20 marks total)
A2: 2D Pivots · Filters · % of Row Total · Date Grouping · Calculated Fields · Cross-Sheet Data
A4: Q# | B4: Question | C4: Marks | D4: Hint | E4: Your Answer | F4: Format
A5: Q4.1 | B5: Build a pivot with sales_region as rows and product category as columns, values = SUM of final_amount. What value appears at the intersection of "South" and "Electronics"? | C5: 4 | D5: You need to add category (from Products) and region (from Sales_Reps) as columns to Orders first. Insert PivotTable from combined data. | E5: =SUMIFS(Orders!I2:I2001, Orders!Q2:Q2001, "South", Orders!N2:N2001, "Electronics") -> 1314107.4 | F5: Currency
A6: Q4.2 | B6: Build a pivot: rows = order month (Jan-24 through Dec-24), columns = sales_rep_id, values = SUM of final_amount. What is the HIGHEST single value in the entire pivot? (One number.) | C6: 4 | D6: After building, use MAX() over the pivot data range, or scan visually. | E6: 216421.52 | F6: Currency
A7: Q4.3 | B7: For the North sales_region only: what PERCENTAGE of total revenue comes from the Apparel category? Configure the pivot with Show Values As → % of Row Total. | C7: 4 | D7: Pivot: rows=region, cols=category, values=sum(final_amount), Show Values As = % of Row Total. | E7: =SUMIFS(Orders!I2:I2001, Orders!Q2:Q2001, "North", Orders!N2:N2001, "Apparel") / SUMIF(Orders!Q2:Q2001, "North", Orders!I2:I2001) -> 0.1402315 | F7: Percentage
A8: Q4.4 | B8: Group order dates by QUARTER in a pivot. What is the total revenue for Q4 2024 (Oct-Dec)? | C8: 4 | D8: PivotTable → Group By → Quarter. Or SUMIFS with date range. | E8: =SUMIFS(Orders!I2:I2001, Orders!B2:B2001, ">=2024-10-01", Orders!B2:B2001, "<=2024-12-31") -> 6459443 | F8: Currency
A9: Q4.5 | B9: Create a CALCULATED FIELD in the pivot: profit_margin = (unit_price - unit_cost) / unit_price. What is the AVERAGE profit_margin for orders shipped to Delhi? Give as a percentage. | C9: 4 | D9: Add unit_cost via VLOOKUP as helper column. Create pivot calculated field, filter to Delhi. | E9: =(SUMIF(Orders!K2:K2001, "*Delhi*", Orders!G2:G2001) - SUMIF(Orders!K2:K2001, "*Delhi*", Orders!R2:R2001)) / SUMIF(Orders!K2:K2001, "*Delhi*", Orders!G2:G2001) -> 0.45972106 | F9: Percentage

Sheet Q5_Advanced
A1: Q5 - ADVANCED (10 marks total)
A2: RANK · Running Totals · TEXTJOIN · LARGE + INDEX/MATCH · Multi-condition top-N
A4: Q# | B4: Question | C4: Marks | D4: Hint | E4: Your Answer | F4: Format
A5: Q5.1 | B5: Rank all sales reps by total revenue (highest = rank 1). Who (name) is at RANK #7? | C5: 2 | D5: Per-rep totals, then use RANK.EQ, or sort. Return the rep_name at position 7. | E5: =INDEX(Sales_Reps!B2:B31, MATCH(7, Sales_Reps!G2:G31, 0)) -> Amit Singh | F5: Text
A6: Q5.2 | B6: What is the CUMULATIVE revenue from Jan 2024 through the end of Aug 2024? (Sum of final_amount where order_date <= 31-Aug-2024.) | C6: 2 | D6: SUMIFS with date <=. | E6: =SUMIFS(Orders!I2:I2001, Orders!B2:B2001, "<=2024-08-31") -> 18050690 | F6: Currency
A7: Q5.3 | B7: Among orders where the sales rep is in the WEST region: which product (by name) has the 2nd highest total revenue? | C7: 3 | D7: Helper: sales_region on orders. Filter/pivot to West, sum by product, rank, get #2, VLOOKUP product name. | E7: =INDEX(Products!B2:B61, MATCH(LARGE(Products!G2:G61, 2), Products!G2:G61, 0)) -> Smart Watch | F7: Text
A8: Q5.4 | B8: Concatenate the names of the top 5 reps by revenue into a single cell, separated by " | " (space-pipe-space). | C8: 2 | D8: TEXTJOIN with delimiter " | ". Combine with LARGE to pull top 5. | E8: =_xlfn.TEXTJOIN(" | ", TRUE, INDEX(Sales_Reps!B2:B31, MATCH(LARGE(Sales_Reps!F2:F31, 1), Sales_Reps!F2:F31, 0)), INDEX(Sales_Reps!B2:B31, MATCH(LARGE(Sales_Reps!F2:F31, 2), Sales_Reps!F2:F31, 0)), INDEX(Sales_Reps!B2:B31, MATCH(LARGE(Sales_Reps!F2:F31, 3), Sales_Reps!F2:F31, 0)), INDEX(Sales_Reps!B2:B31, MATCH(LARGE(Sales_Reps!F2:F31, 4), Sales_Reps!F2:F31, 0)), INDEX(Sales_Reps!B2:B31, MATCH(LARGE(Sales_Reps!F2:F31, 5), Sales_Reps!F2:F31, 0))) -> Neha Desai | Shalini Patel | Deepak Shah | Nisha Menon | Arun Iyer | F8: TEXT
A9: Q5.5 | B9: What is the HIGHEST single order value (final_amount) where ship_city = "Bengaluru" AND the product's category = "Grocery"? | C9: 1 | D9: MAXIFS with a category helper column, or nested MAX(IF()). | E9: =_xlfn.MAXIFS(Orders!I2:I2001, Orders!K2:K2001, "Bengaluru", Orders!N2:N2001, "Grocery") -> 22134 | F9: Currency
